<?xml version="1.0" encoding="utf-8"?>
<!-- This URDF was automatically created by SolidWorks to URDF Exporter! Originally created by Stephen Brawner (brawner@gmail.com) 
     Commit Version: 1.6.0-4-g7f85cfe  Build Version: 1.6.7995.38578
     For more information, please see http://wiki.ros.org/sw_urdf_exporter -->
<robot
  name="dingo_description">
  <link
    name="base_link">
    <inertial>
      <origin
        xyz="0.0014631 -0.00014888 -0.00304"
        rpy="0 0 0" />
      <mass
        value="2.2" />
      <inertia
        ixx="0.0013473"
        ixy="-5.7062E-07"
        ixz="-3.8658E-06"
        iyy="0.0024951"
        iyz="4.4539E-07"
        izz="0.0032361" />
    </inertial>
    <visual>
      <origin
        xyz="0 0 0"
        rpy="0 0 0" />
      <geometry>
        <mesh
          filename="package://dingo_description/meshes/base_link.STL" />
      </geometry>
      <material
        name="">
        <color
          rgba="0.79216 0.81961 0.93333 1" />
      </material>
    </visual>
    <collision>
      <origin
        xyz="0 0 0"
        rpy="0 0 0" />
      <geometry>
        <mesh
          filename="package://dingo_description/meshes/base_link.STL" />
      </geometry>
    </collision>
  </link>
  <link
    name="FL_link1">
    <inertial>
      <origin
        xyz="0.0099246 0.0072705 0.0095717"
        rpy="0 0 0" />
      <mass
        value="0.2" />
      <inertia
        ixx="3.5552E-05"
        ixy="4.3357E-08"
        ixz="2.126E-08"
        iyy="3.3482E-05"
        iyz="-1.3221E-07"
        izz="1.9902E-05" />
    </inertial>
    <visual>
      <origin
        xyz="0 0 0"
        rpy="0 0 0" />
      <geometry>
        <mesh
          filename="package://dingo_description/meshes/FL_link1.STL" />
      </geometry>
      <material
        name="">
        <color
          rgba="0.79216 0.81961 0.93333 1" />
      </material>
    </visual>
    <collision>
      <origin
        xyz="0 0 0"
        rpy="0 0 0" />
      <geometry>
        <mesh
          filename="package://dingo_description/meshes/FL_link1.STL" />
      </geometry>
    </collision>
  </link>
  <joint
    name="FL_theta1"
    type="continuous">
    <origin
      xyz="0.11165 0.061 -0.0144"
      rpy="1.5708 0 1.5708" />
    <parent
      link="base_link" />
    <child
      link="FL_link1" />
    <axis
      xyz="0 0 -1" />
  </joint>
  <link
    name="FL_link2">
    <inertial>
      <origin
        xyz="0.04716 -9.1E-06 0.0027797"
        rpy="0 0 0" />
      <mass
        value="0.05" />
      <inertia
        ixx="2.7283E-06"
        ixy="-6.5997E-10"
        ixz="1.8046E-06"
        iyy="7.2343E-05"
        iyz="-2.0176E-09"
        izz="7.3964E-05" />
    </inertial>
    <visual>
      <origin
        xyz="0 0 0"
        rpy="0 0 0" />
      <geometry>
        <mesh
          filename="package://dingo_description/meshes/FL_link2.STL" />
      </geometry>
      <material
        name="">
        <color
          rgba="0.79216 0.81961 0.93333 1" />
      </material>
    </visual>
    <collision>
      <origin
        xyz="0 0 0"
        rpy="0 0 0" />
      <geometry>
        <mesh
          filename="package://dingo_description/meshes/FL_link2.STL" />
      </geometry>
    </collision>
  </link>
  <joint
    name="FL_theta2"
    type="continuous">
    <origin
      xyz="0.0496 0.0144 0"
      rpy="1.5708 1.5708 -1.5708" />
    <parent
      link="FL_link1" />
    <child
      link="FL_link2" />
    <axis
      xyz="0 0 1" />
  </joint>
  <link
    name="FL_link3">
    <inertial>
      <origin
        xyz="0.050883 0.0040212 0.00066702"
        rpy="0 0 0" />
      <mass
        value="0.05" />
      <inertia
        ixx="4.9316E-06"
        ixy="-7.1103E-06"
        ixz="2.5244E-06"
        iyy="8.9179E-05"
        iyz="2.3247E-07"
        izz="8.8368E-05" />
    </inertial>
    <visual>
      <origin
        xyz="0 0 0"
        rpy="0 0 0" />
      <geometry>
        <mesh
          filename="package://dingo_description/meshes/FL_link3.STL" />
      </geometry>
      <material
        name="">
        <color
          rgba="0.79216 0.81961 0.93333 1" />
      </material>
    </visual>
    <collision>
      <origin
        xyz="0 0 0"
        rpy="0 0 0" />
      <geometry>
        <mesh
          filename="package://dingo_description/meshes/FL_link3.STL" />
      </geometry>
    </collision>
  </link>
  <joint
    name="FL_theta3"
    type="continuous">
    <origin
      xyz="0.13 0 0"
      rpy="0 0 1.5708" />
    <parent
      link="FL_link2" />
    <child
      link="FL_link3" />
    <axis
      xyz="0 0 1" />
  </joint>
  <link
    name="FL_link4">
    <inertial>
      <origin
        xyz="-0.0035222 0.0032708 7.8203E-12"
        rpy="0 0 0" />
      <mass
        value="0.01" />
      <inertia
        ixx="4.34E-08"
        ixy="-1.0272E-08"
        ixz="-3.4038E-16"
        iyy="4.1878E-08"
        iyz="3.1906E-16"
        izz="3.2338E-08" />
    </inertial>
    <visual>
      <origin
        xyz="0 0 0"
        rpy="0 0 0" />
      <geometry>
        <mesh
          filename="package://dingo_description/meshes/FL_link4.STL" />
      </geometry>
      <material
        name="">
        <color
          rgba="0.79216 0.81961 0.93333 1" />
      </material>
    </visual>
    <collision>
      <origin
        xyz="0 0 0"
        rpy="0 0 0" />
      <geometry>
        <mesh
          filename="package://dingo_description/meshes/FL_link4.STL" />
      </geometry>
    </collision>
  </link>
  <joint
    name="FL_foot"
    type="fixed">
    <origin
      xyz="0.13814 0 0"
      rpy="0 0 0" />
    <parent
      link="FL_link3" />
    <child
      link="FL_link4" />
    <axis
      xyz="0 0 0" />
  </joint>
  <link
    name="FR_link1">
    <inertial>
      <origin
        xyz="-0.0099246 0.0072016 0.009573"
        rpy="0 0 0" />
      <mass
        value="0.2" />
      <inertia
        ixx="3.5552E-05"
        ixy="4.3356E-08"
        ixz="-2.0644E-08"
        iyy="3.3482E-05"
        iyz="-1.3216E-07"
        izz="1.9902E-05" />
    </inertial>
    <visual>
      <origin
        xyz="0 0 0"
        rpy="0 0 0" />
      <geometry>
        <mesh
          filename="package://dingo_description/meshes/FR_link1.STL" />
      </geometry>
      <material
        name="">
        <color
          rgba="0.79216 0.81961 0.93333 1" />
      </material>
    </visual>
    <collision>
      <origin
        xyz="0 0 0"
        rpy="0 0 0" />
      <geometry>
        <mesh
          filename="package://dingo_description/meshes/FR_link1.STL" />
      </geometry>
    </collision>
  </link>
  <joint
    name="FR_theta1"
    type="continuous">
    <origin
      xyz="0.11165 -0.061 -0.0144"
      rpy="1.5708 0 1.5708" />
    <parent
      link="base_link" />
    <child
      link="FR_link1" />
    <axis
      xyz="0 0 -1" />
  </joint>
  <link
    name="FR_link2">
    <inertial>
      <origin
        xyz="0.047105 -3.823E-07 -0.0027801"
        rpy="0 0 0" />
      <mass
        value="0.05" />
      <inertia
        ixx="2.7284E-06"
        ixy="-2.0045E-09"
        ixz="-1.7926E-06"
        iyy="7.2365E-05"
        iyz="8.4078E-11"
        izz="7.3986E-05" />
    </inertial>
    <visual>
      <origin
        xyz="0 0 0"
        rpy="0 0 0" />
      <geometry>
        <mesh
          filename="package://dingo_description/meshes/FR_link2.STL" />
      </geometry>
      <material
        name="">
        <color
          rgba="0.79216 0.81961 0.93333 1" />
      </material>
    </visual>
    <collision>
      <origin
        xyz="0 0 0"
        rpy="0 0 0" />
      <geometry>
        <mesh
          filename="package://dingo_description/meshes/FR_link2.STL" />
      </geometry>
    </collision>
  </link>
  <joint
    name="FR_theta2"
    type="continuous">
    <origin
      xyz="-0.0496 0.0144 0"
      rpy="1.5708 1.5708 -1.5708" />
    <parent
      link="FR_link1" />
    <child
      link="FR_link2" />
    <axis
      xyz="0 0 1" />
  </joint>
  <link
    name="FR_link3">
    <inertial>
      <origin
        xyz="0.050883 0.0040212 -0.00066701"
        rpy="0 0 0" />
      <mass
        value="0.05" />
      <inertia
        ixx="4.9316E-06"
        ixy="-7.1103E-06"
        ixz="-2.5245E-06"
        iyy="8.9179E-05"
        iyz="-2.3248E-07"
        izz="8.8368E-05" />
    </inertial>
    <visual>
      <origin
        xyz="0 0 0"
        rpy="0 0 0" />
      <geometry>
        <mesh
          filename="package://dingo_description/meshes/FR_link3.STL" />
      </geometry>
      <material
        name="">
        <color
          rgba="0.79216 0.81961 0.93333 1" />
      </material>
    </visual>
    <collision>
      <origin
        xyz="0 0 0"
        rpy="0 0 0" />
      <geometry>
        <mesh
          filename="package://dingo_description/meshes/FR_link3.STL" />
      </geometry>
    </collision>
  </link>
  <joint
    name="FR_theta3"
    type="continuous">
    <origin
      xyz="0.13 0 0"
      rpy="0 0 1.5708" />
    <parent
      link="FR_link2" />
    <child
      link="FR_link3" />
    <axis
      xyz="0 0 1" />
  </joint>
  <link
    name="FR_link4">
    <inertial>
      <origin
        xyz="-0.0035222 0.0032708 6.3288E-11"
        rpy="0 0 0" />
      <mass
        value="0.01" />
      <inertia
        ixx="4.34E-08"
        ixy="-1.0272E-08"
        ixz="-5.1458E-16"
        iyy="4.1878E-08"
        iyz="4.8083E-16"
        izz="3.2338E-08" />
    </inertial>
    <visual>
      <origin
        xyz="0 0 0"
        rpy="0 0 0" />
      <geometry>
        <mesh
          filename="package://dingo_description/meshes/FR_link4.STL" />
      </geometry>
      <material
        name="">
        <color
          rgba="0.79216 0.81961 0.93333 1" />
      </material>
    </visual>
    <collision>
      <origin
        xyz="0 0 0"
        rpy="0 0 0" />
      <geometry>
        <mesh
          filename="package://dingo_description/meshes/FR_link4.STL" />
      </geometry>
    </collision>
  </link>
  <joint
    name="FR_foot"
    type="fixed">
    <origin
      xyz="0.13814 0 0"
      rpy="0 0 0" />
    <parent
      link="FR_link3" />
    <child
      link="FR_link4" />
    <axis
      xyz="0 0 0" />
  </joint>
  <link
    name="RL_link1">
    <inertial>
      <origin
        xyz="0.0099246 0.0072017 0.010375"
        rpy="0 0 0" />
      <mass
        value="0.2" />
      <inertia
        ixx="3.5552E-05"
        ixy="-4.3357E-08"
        ixz="2.0644E-08"
        iyy="3.3482E-05"
        iyz="-1.3221E-07"
        izz="1.9902E-05" />
    </inertial>
    <visual>
      <origin
        xyz="0 0 0"
        rpy="0 0 0" />
      <geometry>
        <mesh
          filename="package://dingo_description/meshes/RL_link1.STL" />
      </geometry>
      <material
        name="">
        <color
          rgba="0.79216 0.81961 0.93333 1" />
      </material>
    </visual>
    <collision>
      <origin
        xyz="0 0 0"
        rpy="0 0 0" />
      <geometry>
        <mesh
          filename="package://dingo_description/meshes/RL_link1.STL" />
      </geometry>
    </collision>
  </link>
  <joint
    name="RL_theta1"
    type="continuous">
    <origin
      xyz="-0.11165 0.061 -0.0144"
      rpy="1.5708 0 1.5708" />
    <parent
      link="base_link" />
    <child
      link="RL_link1" />
    <axis
      xyz="0 0 -1" />
  </joint>
  <link
    name="RL_link2">
    <inertial>
      <origin
        xyz="0.04716 -9.1001E-06 0.0027797"
        rpy="0 0 0" />
      <mass
        value="0.05" />
      <inertia
        ixx="2.7283E-06"
        ixy="-6.5997E-10"
        ixz="1.8046E-06"
        iyy="7.2343E-05"
        iyz="-2.0176E-09"
        izz="7.3964E-05" />
    </inertial>
    <visual>
      <origin
        xyz="0 0 0"
        rpy="0 0 0" />
      <geometry>
        <mesh
          filename="package://dingo_description/meshes/RL_link2.STL" />
      </geometry>
      <material
        name="">
        <color
          rgba="0.79216 0.81961 0.93333 1" />
      </material>
    </visual>
    <collision>
      <origin
        xyz="0 0 0"
        rpy="0 0 0" />
      <geometry>
        <mesh
          filename="package://dingo_description/meshes/RL_link2.STL" />
      </geometry>
    </collision>
  </link>
  <joint
    name="RL_theta2"
    type="continuous">
    <origin
      xyz="0.0496 0.0144 0"
      rpy="1.5708 1.5708 -1.5708" />
    <parent
      link="RL_link1" />
    <child
      link="RL_link2" />
    <axis
      xyz="0 0 1" />
  </joint>
  <link
    name="RL_link3">
    <inertial>
      <origin
        xyz="0.050883 0.0040212 0.00066703"
        rpy="0 0 0" />
      <mass
        value="0.05" />
      <inertia
        ixx="4.9316E-06"
        ixy="-7.1103E-06"
        ixz="2.5244E-06"
        iyy="8.9179E-05"
        iyz="2.3247E-07"
        izz="8.8368E-05" />
    </inertial>
    <visual>
      <origin
        xyz="0 0 0"
        rpy="0 0 0" />
      <geometry>
        <mesh
          filename="package://dingo_description/meshes/RL_link3.STL" />
      </geometry>
      <material
        name="">
        <color
          rgba="0.79216 0.81961 0.93333 1" />
      </material>
    </visual>
    <collision>
      <origin
        xyz="0 0 0"
        rpy="0 0 0" />
      <geometry>
        <mesh
          filename="package://dingo_description/meshes/RL_link3.STL" />
      </geometry>
    </collision>
  </link>
  <joint
    name="RL_theta3"
    type="continuous">
    <origin
      xyz="0.13 0 0"
      rpy="0 0 1.5708" />
    <parent
      link="RL_link2" />
    <child
      link="RL_link3" />
    <axis
      xyz="0 0 1" />
  </joint>
  <link
    name="RL_link4">
    <inertial>
      <origin
        xyz="-0.0035222 0.0032708 6.3535E-10"
        rpy="0 0 0" />
      <mass
        value="0.01" />
      <inertia
        ixx="4.34E-08"
        ixy="-1.0272E-08"
        ixz="-2.3143E-15"
        iyy="4.1878E-08"
        iyz="2.1487E-15"
        izz="3.2338E-08" />
    </inertial>
    <visual>
      <origin
        xyz="0 0 0"
        rpy="0 0 0" />
      <geometry>
        <mesh
          filename="package://dingo_description/meshes/RL_link4.STL" />
      </geometry>
      <material
        name="">
        <color
          rgba="0.79216 0.81961 0.93333 1" />
      </material>
    </visual>
    <collision>
      <origin
        xyz="0 0 0"
        rpy="0 0 0" />
      <geometry>
        <mesh
          filename="package://dingo_description/meshes/RL_link4.STL" />
      </geometry>
    </collision>
  </link>
  <joint
    name="RL_foot"
    type="fixed">
    <origin
      xyz="0.13814 0 0"
      rpy="0 0 0" />
    <parent
      link="RL_link3" />
    <child
      link="RL_link4" />
    <axis
      xyz="0 0 0" />
  </joint>
  <link
    name="RR_link1">
    <inertial>
      <origin
        xyz="-0.0099246 0.0072016 0.010375"
        rpy="0 0 0" />
      <mass
        value="0.2" />
      <inertia
        ixx="3.5552E-05"
        ixy="4.3356E-08"
        ixz="-2.0644E-08"
        iyy="3.3482E-05"
        iyz="-1.3216E-07"
        izz="1.9902E-05" />
    </inertial>
    <visual>
      <origin
        xyz="0 0 0"
        rpy="0 0 0" />
      <geometry>
        <mesh
          filename="package://dingo_description/meshes/RR_link1.STL" />
      </geometry>
      <material
        name="">
        <color
          rgba="0.79216 0.81961 0.93333 1" />
      </material>
    </visual>
    <collision>
      <origin
        xyz="0 0 0"
        rpy="0 0 0" />
      <geometry>
        <mesh
          filename="package://dingo_description/meshes/RR_link1.STL" />
      </geometry>
    </collision>
  </link>
  <joint
    name="RR_theta1"
    type="continuous">
    <origin
      xyz="-0.11165 -0.061 -0.0144"
      rpy="1.5708 0 1.5708" />
    <parent
      link="base_link" />
    <child
      link="RR_link1" />
    <axis
      xyz="0 0 -1" />
  </joint>
  <link
    name="RR_link2">
    <inertial>
      <origin
        xyz="0.047105 -3.823E-07 -0.0027801"
        rpy="0 0 0" />
      <mass
        value="0.05" />
      <inertia
        ixx="2.7284E-06"
        ixy="-2.0045E-09"
        ixz="-1.7926E-06"
        iyy="7.2365E-05"
        iyz="8.4078E-11"
        izz="7.3986E-05" />
    </inertial>
    <visual>
      <origin
        xyz="0 0 0"
        rpy="0 0 0" />
      <geometry>
        <mesh
          filename="package://dingo_description/meshes/RR_link2.STL" />
      </geometry>
      <material
        name="">
        <color
          rgba="0.79216 0.81961 0.93333 1" />
      </material>
    </visual>
    <collision>
      <origin
        xyz="0 0 0"
        rpy="0 0 0" />
      <geometry>
        <mesh
          filename="package://dingo_description/meshes/RR_link2.STL" />
      </geometry>
    </collision>
  </link>
  <joint
    name="RR_theta2"
    type="continuous">
    <origin
      xyz="-0.0496 0.0144 0"
      rpy="1.5708 1.5708 -1.5708" />
    <parent
      link="RR_link1" />
    <child
      link="RR_link2" />
    <axis
      xyz="0 0 1" />
  </joint>
  <link
    name="RR_link3">
    <inertial>
      <origin
        xyz="0.050883 0.0040212 -0.00066701"
        rpy="0 0 0" />
      <mass
        value="0.05" />
      <inertia
        ixx="4.9316E-06"
        ixy="-7.1103E-06"
        ixz="-2.5245E-06"
        iyy="8.9179E-05"
        iyz="-2.3248E-07"
        izz="8.8368E-05" />
    </inertial>
    <visual>
      <origin
        xyz="0 0 0"
        rpy="0 0 0" />
      <geometry>
        <mesh
          filename="package://dingo_description/meshes/RR_link3.STL" />
      </geometry>
      <material
        name="">
        <color
          rgba="0.79216 0.81961 0.93333 1" />
      </material>
    </visual>
    <collision>
      <origin
        xyz="0 0 0"
        rpy="0 0 0" />
      <geometry>
        <mesh
          filename="package://dingo_description/meshes/RR_link3.STL" />
      </geometry>
    </collision>
  </link>
  <joint
    name="RR_theta3"
    type="continuous">
    <origin
      xyz="0.13 0 0"
      rpy="0 0 1.5708" />
    <parent
      link="RR_link2" />
    <child
      link="RR_link3" />
    <axis
      xyz="0 0 1" />
  </joint>
  <link
    name="RR_link4">
    <inertial>
      <origin
        xyz="-0.0035222 0.0032708 7.8203E-12"
        rpy="0 0 0" />
      <mass
        value="0.01" />
      <inertia
        ixx="4.34E-08"
        ixy="-1.0272E-08"
        ixz="-3.4038E-16"
        iyy="4.1878E-08"
        iyz="3.1906E-16"
        izz="3.2338E-08" />
    </inertial>
    <visual>
      <origin
        xyz="0 0 0"
        rpy="0 0 0" />
      <geometry>
        <mesh
          filename="package://dingo_description/meshes/RR_link4.STL" />
      </geometry>
      <material
        name="">
        <color
          rgba="0.79216 0.81961 0.93333 1" />
      </material>
    </visual>
    <collision>
      <origin
        xyz="0 0 0"
        rpy="0 0 0" />
      <geometry>
        <mesh
          filename="package://dingo_description/meshes/RR_link4.STL" />
      </geometry>
    </collision>
  </link>
  <joint
    name="RR_foot"
    type="fixed">
    <origin
      xyz="0.13814 0 0"
      rpy="0 0 0" />
    <parent
      link="RR_link3" />
    <child
      link="RR_link4" />
    <axis
      xyz="0 0 0" />
  </joint>
</robot>