<?xml version="1.0" encoding="utf-8"?>
<!-- This URDF was automatically created by SolidWorks to URDF Exporter! Originally created by Stephen Brawner (brawner@gmail.com) 
     Commit Version: 1.6.0-4-g7f85cfe  Build Version: 1.6.7995.38578
     For more information, please see http://wiki.ros.org/sw_urdf_exporter -->
<robot name="dingo" xmlns:xacro="http://www.ros.org/wiki/xacro">

  <!-- Maximum torque -->
  <xacro:property name="effort_limit" value="1.4" />

  <!-- base_link -->
  <link
    name="base_link">
    <inertial>
      <origin
        xyz="0.017757 -0.00014888 -0.00304"
        rpy="0 0 0" />
      <mass
        value="2.2" />
      <inertia
        ixx="0.0013473"
        ixy="-5.7062E-07"
        ixz="-3.8658E-06"
        iyy="0.0024951"
        iyz="4.4539E-07"
        izz="0.0032361" />
    </inertial>
    <visual>
      <origin
        xyz="0 0 0"
        rpy="0 0 0" />
      <geometry>
        <mesh
          filename="package://dingo_description/meshes/base_link.dae" />
      </geometry>
      <material
        name="">
        <color
          rgba="0.79216 0.81961 0.93333 1" />
      </material>
    </visual>
    <collision>
      <origin
        xyz="0 0 0"
        rpy="0 0 0" />
      <geometry>
        <mesh
          filename="package://dingo_description/meshes/base_collision.STL" />
      </geometry>
    </collision>
  </link>

  <!-- FL_link1 -->
  <link
    name="FL_link1">
    <inertial>
      <origin
        xyz="0.0099246 0.0072705 0.0095717"
        rpy="0 0 0" />
      <mass
        value="0.2" />
      <inertia
        ixx="3.5552E-05"
        ixy="4.3357E-08"
        ixz="2.126E-08"
        iyy="3.3482E-05"
        iyz="-1.3221E-07"
        izz="1.9902E-05" />
    </inertial>
    <visual>
      <origin
        xyz="0 0 0"
        rpy="0 0 0" />
      <geometry>
        <mesh
          filename="package://dingo_description/meshes/FL_link1.dae" />
      </geometry>
      <material
        name="">
        <color
          rgba="0.79216 0.81961 0.93333 1" />
      </material>
    </visual>
    <collision>
      <origin
        xyz="0 0 0"
        rpy="0 0 0" />
      <geometry>
        <mesh
          filename="package://dingo_description/meshes/L_link1_collision.STL" />
      </geometry>
    </collision>
  </link>

  <!-- FL_link2 -->
  <link
    name="FL_link2">
    <inertial>
      <origin
        xyz="0.04716 -9.1E-06 0.0027797"
        rpy="0 0 0" />
      <mass
        value="0.05" />
      <inertia
        ixx="2.7283E-06"
        ixy="-6.5997E-10"
        ixz="1.8046E-06"
        iyy="7.2343E-05"
        iyz="-2.0176E-09"
        izz="7.3964E-05" />
    </inertial>
    <visual>
      <origin
        xyz="0 0 0"
        rpy="0 0 0" />
      <geometry>
        <mesh
          filename="package://dingo_description/meshes/L_link2.dae" />
      </geometry>
      <material
        name="">
        <color
          rgba="0.79216 0.81961 0.93333 1" />
      </material>
    </visual>
    <collision>
      <origin
        xyz="0 0 0"
        rpy="0 0 0" />
      <geometry>
        <mesh
          filename="package://dingo_description/meshes/L_link2_collision.STL" />
      </geometry>
    </collision>
  </link>

  <!-- FL_link3 -->
  <link
    name="FL_link3">
    <inertial>
      <origin
        xyz="0.050883 0.0040212 0.00066702"
        rpy="0 0 0" />
      <mass
        value="0.05" />
      <inertia
        ixx="4.9316E-06"
        ixy="-7.1103E-06"
        ixz="2.5244E-06"
        iyy="8.9179E-05"
        iyz="2.3247E-07"
        izz="8.8368E-05" />
    </inertial>
    <visual>
      <origin
        xyz="0 0 0"
        rpy="0 0 0" />
      <geometry>
        <mesh
          filename="package://dingo_description/meshes/L_link3.dae" />
      </geometry>
      <material
        name="">
        <color
          rgba="0.79216 0.81961 0.93333 1" />
      </material>
    </visual>
    <collision>
      <origin
        xyz="0 0 0"
        rpy="0 0 0" />
      <geometry>
        <mesh
          filename="package://dingo_description/meshes/L_link3_collision.STL" />
      </geometry>
    </collision>
  </link>

  <!-- FL_link4 -->
  <link
    name="FL_link4">
    <inertial>
      <origin
        xyz="-0.0035222 0.0032708 7.8202E-12"
        rpy="0 0 0" />
      <mass
        value="0.01" />
      <inertia
        ixx="4.34E-08"
        ixy="-1.0272E-08"
        ixz="-3.4038E-16"
        iyy="4.1878E-08"
        iyz="3.1906E-16"
        izz="3.2338E-08" />
    </inertial>
    <visual>
      <origin
        xyz="0 0 0"
        rpy="0 0 0" />
      <geometry>
        <mesh
          filename="package://dingo_description/meshes/link4.dae" />
      </geometry>
      <material
        name="">
        <color
          rgba="0.79216 0.81961 0.93333 1" />
      </material>
    </visual>
    <collision>
      <origin
        xyz="0 0 0"
        rpy="0 0 0" />
      <geometry>
        <mesh
          filename="package://dingo_description/meshes/link4_collision.STL" />
      </geometry>
    </collision>
  </link>

  <!-- FR_link1 -->
  <link
    name="FR_link1">
    <inertial>
      <origin
        xyz="-0.0099246 0.0072016 0.009573"
        rpy="0 0 0" />
      <mass
        value="0.2" />
      <inertia
        ixx="3.5552E-05"
        ixy="4.3356E-08"
        ixz="-2.0644E-08"
        iyy="3.3482E-05"
        iyz="-1.3216E-07"
        izz="1.9902E-05" />
    </inertial>
    <visual>
      <origin
        xyz="0 0 0"
        rpy="0 0 0" />
      <geometry>
        <mesh
          filename="package://dingo_description/meshes/FR_link1.dae" />
      </geometry>
      <material
        name="">
        <color
          rgba="0.79216 0.81961 0.93333 1" />
      </material>
    </visual>
    <collision>
      <origin
        xyz="0 0 0"
        rpy="0 0 0" />
      <geometry>
        <mesh
          filename="package://dingo_description/meshes/R_link1_collision.STL" />
      </geometry>
    </collision>
  </link>

  <!-- FR_link2 -->
  <link
    name="FR_link2">
    <inertial>
      <origin
        xyz="0.047105 -3.823E-07 -0.0027801"
        rpy="0 0 0" />
      <mass
        value="0.05" />
      <inertia
        ixx="2.7284E-06"
        ixy="-2.0045E-09"
        ixz="-1.7926E-06"
        iyy="7.2365E-05"
        iyz="8.4078E-11"
        izz="7.3986E-05" />
    </inertial>
    <visual>
      <origin
        xyz="0 0 0"
        rpy="0 0 0" />
      <geometry>
        <mesh
          filename="package://dingo_description/meshes/R_link2.dae" />
      </geometry>
      <material
        name="">
        <color
          rgba="0.79216 0.81961 0.93333 1" />
      </material>
    </visual>
    <collision>
      <origin
        xyz="0 0 0"
        rpy="0 0 0" />
      <geometry>
        <mesh
          filename="package://dingo_description/meshes/R_link2_collision.STL" />
      </geometry>
    </collision>
  </link>

  <!-- FR_link3 -->
  <link
    name="FR_link3">
    <inertial>
      <origin
        xyz="0.050883 0.0040212 -0.00066701"
        rpy="0 0 0" />
      <mass
        value="0.05" />
      <inertia
        ixx="4.9316E-06"
        ixy="-7.1103E-06"
        ixz="-2.5245E-06"
        iyy="8.9179E-05"
        iyz="-2.3248E-07"
        izz="8.8368E-05" />
    </inertial>
    <visual>
      <origin
        xyz="0 0 0"
        rpy="0 0 0" />
      <geometry>
        <mesh
          filename="package://dingo_description/meshes/R_link3.dae" />
      </geometry>
      <material
        name="">
        <color
          rgba="0.79216 0.81961 0.93333 1" />
      </material>
    </visual>
    <collision>
      <origin
        xyz="0 0 0"
        rpy="0 0 0" />
      <geometry>
        <mesh
          filename="package://dingo_description/meshes/R_link3_collision.STL" />
      </geometry>
    </collision>
  </link>

  <!-- FR_link4 -->
  <link
    name="FR_link4">
    <inertial>
      <origin
        xyz="-0.0035222 0.0032708 6.3288E-11"
        rpy="0 0 0" />
      <mass
        value="0.01" />
      <inertia
        ixx="4.34E-08"
        ixy="-1.0272E-08"
        ixz="-5.1458E-16"
        iyy="4.1878E-08"
        iyz="4.8083E-16"
        izz="3.2338E-08" />
    </inertial>
    <visual>
      <origin
        xyz="0 0 0"
        rpy="0 0 0" />
      <geometry>
        <mesh
          filename="package://dingo_description/meshes/link4.dae" />
      </geometry>
      <material
        name="">
        <color
          rgba="0.79216 0.81961 0.93333 1" />
      </material>
    </visual>
    <collision>
      <origin
        xyz="0 0 0"
        rpy="0 0 0" />
      <geometry>
        <mesh
          filename="package://dingo_description/meshes/link4_collision.STL" />
      </geometry>
    </collision>
  </link>

  <!-- RL_link1 -->
  <link
    name="RL_link1">
    <inertial>
      <origin
        xyz="0.0099246 0.0072017 0.010375"
        rpy="0 0 0" />
      <mass
        value="0.2" />
      <inertia
        ixx="3.5552E-05"
        ixy="-4.3357E-08"
        ixz="2.0644E-08"
        iyy="3.3482E-05"
        iyz="-1.3221E-07"
        izz="1.9902E-05" />
    </inertial>
    <visual>
      <origin
        xyz="0 0 0"
        rpy="0 0 0" />
      <geometry>
        <mesh
          filename="package://dingo_description/meshes/RL_link1.dae" />
      </geometry>
      <material
        name="">
        <color
          rgba="0.79216 0.81961 0.93333 1" />
      </material>
    </visual>
    <collision>
      <origin
        xyz="0 0 0"
        rpy="0 0 0" />
      <geometry>
        <mesh
          filename="package://dingo_description/meshes/L_link1_collision.STL" />
      </geometry>
    </collision>
  </link>
  
  <!-- RL_link2 -->
  <link
    name="RL_link2">
    <inertial>
      <origin
        xyz="0.04716 -9.1001E-06 0.0027797"
        rpy="0 0 0" />
      <mass
        value="0.05" />
      <inertia
        ixx="2.7283E-06"
        ixy="-6.5997E-10"
        ixz="1.8046E-06"
        iyy="7.2343E-05"
        iyz="-2.0176E-09"
        izz="7.3964E-05" />
    </inertial>
    <visual>
      <origin
        xyz="0 0 0"
        rpy="0 0 0" />
      <geometry>
        <mesh
          filename="package://dingo_description/meshes/L_link2.dae" />
      </geometry>
      <material
        name="">
        <color
          rgba="0.79216 0.81961 0.93333 1" />
      </material>
    </visual>
    <collision>
      <origin
        xyz="0 0 0"
        rpy="0 0 0" />
      <geometry>
        <mesh
          filename="package://dingo_description/meshes/L_link2_collision.STL" />
      </geometry>
    </collision>
  </link>

  <!-- RL_link3 -->
  <link
    name="RL_link3">
    <inertial>
      <origin
        xyz="0.050883 0.0040212 0.00066703"
        rpy="0 0 0" />
      <mass
        value="0.05" />
      <inertia
        ixx="4.9316E-06"
        ixy="-7.1103E-06"
        ixz="2.5244E-06"
        iyy="8.9179E-05"
        iyz="2.3247E-07"
        izz="8.8368E-05" />
    </inertial>
    <visual>
      <origin
        xyz="0 0 0"
        rpy="0 0 0" />
      <geometry>
        <mesh
          filename="package://dingo_description/meshes/L_link3.dae" />
      </geometry>
      <material
        name="">
        <color
          rgba="0.79216 0.81961 0.93333 1" />
      </material>
    </visual>
    <collision>
      <origin
        xyz="0 0 0"
        rpy="0 0 0" />
      <geometry>
        <mesh
          filename="package://dingo_description/meshes/L_link3_collision.STL" />
      </geometry>
    </collision>
  </link>

  <!-- RL_link4 -->
  <link
    name="RL_link4">
    <inertial>
      <origin
        xyz="-0.0035222 0.0032708 6.3535E-10"
        rpy="0 0 0" />
      <mass
        value="0.01" />
      <inertia
        ixx="4.34E-08"
        ixy="-1.0272E-08"
        ixz="-2.3143E-15"
        iyy="4.1878E-08"
        iyz="2.1487E-15"
        izz="3.2338E-08" />
    </inertial>
    <visual>
      <origin
        xyz="0 0 0"
        rpy="0 0 0" />
      <geometry>
        <mesh
          filename="package://dingo_description/meshes/link4.dae" />
      </geometry>
      <material
        name="">
        <color
          rgba="0.79216 0.81961 0.93333 1" />
      </material>
    </visual>
    <collision>
      <origin
        xyz="0 0 0"
        rpy="0 0 0" />
      <geometry>
        <mesh
          filename="package://dingo_description/meshes/link4_collision.STL" />
      </geometry>
    </collision>
  </link>

  <!-- RR_link1 -->
  <link
    name="RR_link1">
    <inertial>
      <origin
        xyz="0.0014631 -0.00014888 -0.00304"
        rpy="0 0 0" />
      <mass
        value="0.2" />
      <!-- inertia
        ixx="3.5552E-05"
        ixy="-4.3357E-08"
        ixz="2.0644E-08"
        iyy="3.3482E-05"
        iyz="-1.3221E-07"
        izz="1.9902E-05" /> -->
      <inertia
        ixx="0.0013473"
        ixy="-5.7062E-07"
        ixz="-3.8658E-06"
        iyy="0.0024951"
        iyz="4.4539E-07"
        izz="0.0032361" />
    </inertial>
    <visual>
      <origin
        xyz="0 0 0"
        rpy="0 0 0" />
      <geometry>
        <mesh
          filename="package://dingo_description/meshes/RR_link1.dae" />
      </geometry>
      <material
        name="">
        <color
          rgba="0.79216 0.81961 0.93333 1" />
      </material>
    </visual>
    <collision>
      <origin
        xyz="0 0 0"
        rpy="0 0 0" />
      <geometry>
        <mesh
          filename="package://dingo_description/meshes/R_link1_collision.STL" />
      </geometry>
    </collision>
  </link>

  <!-- RR_link2 -->
  <link
    name="RR_link2">
    <inertial>
      <origin
        xyz="0.047105 -3.823E-07 -0.0027801"
        rpy="0 0 0" />
      <mass
        value="0.05" />
      <inertia
        ixx="2.7284E-06"
        ixy="-2.0045E-09"
        ixz="-1.7926E-06"
        iyy="7.2365E-05"
        iyz="8.4078E-11"
        izz="7.3986E-05" />
    </inertial>
    <visual>
      <origin
        xyz="0 0 0"
        rpy="0 0 0" />
      <geometry>
        <mesh
          filename="package://dingo_description/meshes/R_link2.dae" />
      </geometry>
      <material
        name="">
        <color
          rgba="0.79216 0.81961 0.93333 1" />
      </material>
    </visual>
    <collision>
      <origin
        xyz="0 0 0"
        rpy="0 0 0" />
      <geometry>
        <mesh
          filename="package://dingo_description/meshes/R_link2_collision.STL" />
      </geometry>
    </collision>
  </link>

  <!-- RR_link3 -->
  <link
    name="RR_link3">
    <inertial>
      <origin
        xyz="0.050883 0.0040212 -0.00066701"
        rpy="0 0 0" />
      <mass
        value="0.05" />
      <inertia
        ixx="4.9316E-06"
        ixy="-7.1103E-06"
        ixz="-2.5245E-06"
        iyy="8.9179E-05"
        iyz="-2.3248E-07"
        izz="8.8368E-05" />
    </inertial>
    <visual>
      <origin
        xyz="0 0 0"
        rpy="0 0 0" />
      <geometry>
        <mesh
          filename="package://dingo_description/meshes/R_link3.dae" />
      </geometry>
      <material
        name="">
        <color
          rgba="0.79216 0.81961 0.93333 1" />
      </material>
    </visual>
    <collision>
      <origin
        xyz="0 0 0"
        rpy="0 0 0" />
      <geometry>
        <mesh
          filename="package://dingo_description/meshes/R_link3_collision.STL" />
      </geometry>
    </collision>
  </link>

  <!-- RR_link4 -->
  <link
    name="RR_link4">
    <inertial>
      <origin
        xyz="-0.0035222 0.0032708 7.8203E-12"
        rpy="0 0 0" />
      <mass
        value="0.01" />
      <inertia
        ixx="4.34E-08"
        ixy="-1.0272E-08"
        ixz="-3.4038E-16"
        iyy="4.1878E-08"
        iyz="3.1906E-16"
        izz="3.2338E-08" />
    </inertial>
    <visual>
      <origin
        xyz="0 0 0"
        rpy="0 0 0" />
      <geometry>
        <mesh
          filename="package://dingo_description/meshes/link4.dae" />
      </geometry>
      <material
        name="">
        <color
          rgba="0.79216 0.81961 0.93333 1" />
      </material>
    </visual>
    <collision>
      <origin
        xyz="0 0 0"
        rpy="0 0 0" />
      <geometry>
        <mesh
          filename="package://dingo_description/meshes/link4_collision.STL" />
      </geometry>
    </collision>
  </link>



  <!-- JOINTS -->
  
  <joint
    name="FL_theta1"
    type="continuous">
    <origin
      xyz="0.11165 0.061 -0.0144"
      rpy="1.5708 0 1.5708" />
    <parent
      link="base_link" />
    <child
      link="FL_link1" />
    <axis
      xyz="0 0 1" />
  </joint>
  <joint
    name="FL_theta2"
    type="continuous">
    <origin
      xyz="0.0496000007984339 0.014400000013256 0"
      rpy="1.57079634307336 1.57079568414183 -1.57079631051644" />
    <parent
      link="FL_link1" />
    <child
      link="FL_link2" />
    <axis
      xyz="0 0 1" />
  </joint>
  <joint
    name="FL_theta3"
    type="continuous">
    <origin
      xyz="0.129999999999897 0 0"
      rpy="0 0 1.57079594774422" />
    <parent
      link="FL_link2" />
    <child
      link="FL_link3" />
    <axis
      xyz="0 0 1" />
  </joint>
  <joint
    name="FL_foot"
    type="fixed">
    <origin
      xyz="0.138136646352288 0 0"
      rpy="0 0 0" />
    <parent
      link="FL_link3" />
    <child
      link="FL_link4" />
    <axis
      xyz="0 0 0" />
  </joint>



  <joint
    name="FR_theta1"
    type="continuous">
    <origin
      xyz="0.111650000000002 -0.0609999999999988 -0.0144000000000242"
      rpy="1.57079632679492 0 1.5707963267949" />
    <parent
      link="base_link" />
    <child
      link="FR_link1" />
    <axis
      xyz="0 0 -1" />
  </joint>
  <joint
    name="FR_theta2"
    type="continuous">
    <origin
      xyz="-0.0495999992169121 0.0144000000000242 0"
      rpy="1.57079632309575 1.57079572077363 -1.57079633049404" />
    <parent
      link="FR_link1" />
    <child
      link="FR_link2" />
    <axis
      xyz="0 0 1" />
  </joint>
  <joint
    name="FR_theta3"
    type="continuous">
    <origin
      xyz="0.13000000353672 0 0"
      rpy="0 0 1.57079598438978" />
    <parent
      link="FR_link2" />
    <child
      link="FR_link3" />
    <axis
      xyz="0 0 1" />
  </joint>
  <joint
    name="FR_foot"
    type="fixed">
    <origin
      xyz="0.13813664635243 0 0"
      rpy="0 0 0" />
    <parent
      link="FR_link3" />
    <child
      link="FR_link4" />
    <axis
      xyz="0 0 0" />
  </joint>




  <joint
    name="RL_theta1"
    type="continuous">
    <origin
      xyz="-0.11165 0.061 -0.0144"
      rpy="1.5708 0 1.5708" />
    <parent
      link="base_link" />
    <child
      link="RL_link1" />
    <axis
      xyz="0 0 1" />
  </joint>
  <joint
    name="RL_theta2"
    type="continuous">
    <origin
      xyz="0.0496000007984574 0.014399999996394 0"
      rpy="1.5707963301177 1.57079568414183 -1.57079632347209" />
    <parent
      link="RL_link1" />
    <child
      link="RL_link2" />
    <axis
      xyz="0 0 1" />
  </joint>
  <joint
    name="RL_theta3"
    type="continuous">
    <origin
      xyz="0.129999999994849 0 0"
      rpy="0 0 1.57079594787326" />
    <parent
      link="RL_link2" />
    <child
      link="RL_link3" />
    <axis
      xyz="0 0 0.999999999999979" />
  </joint>
  <joint
    name="RL_foot"
    type="fixed">
    <origin
      xyz="0.138136646352323 0 0"
      rpy="0 0 0" />
    <parent
      link="RL_link3" />
    <child
      link="RL_link4" />
    <axis
      xyz="0 0 0" />
  </joint>



  <joint
    name="RR_theta1"
    type="continuous">
    <origin
      xyz="-0.111650000000003 -0.0609999999999995 -0.0144000000000178"
      rpy="1.57079632679492 0 1.5707963267949" />
    <parent
      link="base_link" />
    <child
      link="RR_link1" />
    <axis
      xyz="0 0 -1" />
  </joint>
  <joint
    name="RR_theta2"
    type="continuous">
    <origin
      xyz="-0.0495999992169147 0.0144000000000178 0"
      rpy="1.57079631992506 1.57079572077363 -1.57079633366473" />
    <parent
      link="RR_link1" />
    <child
      link="RR_link2" />
    <axis
      xyz="0 0 1" />
  </joint>
  <joint
    name="RR_theta3"
    type="continuous">
    <origin
      xyz="0.13000000353672 0 0"
      rpy="0 0 1.57079598438978" />
    <parent
      link="RR_link2" />
    <child
      link="RR_link3" />
    <axis
      xyz="0 0 0.999999999999998" />
  </joint>
  <joint
    name="RR_foot"
    type="fixed">
    <origin
      xyz="0.138136646352431 0 0"
      rpy="0 0 0" />
    <parent
      link="RR_link3" />
    <child
      link="RR_link4" />
    <axis
      xyz="0 0 0" />
  </joint>





  <!-- ROS control plugin -->
  <gazebo>
    <plugin name="gazebo_ros_control" filename="libgazebo_ros_control.so">
      <robotNamespace>dingo_controller</robotNamespace>
    </plugin>
  </gazebo>


  <!-- IMU sensor -->
  <gazebo reference="base_link">
    <gravity>true</gravity>
    <sensor name="imu_sensor" type="imu">
      <always_on>true</always_on>
      <update_rate>100</update_rate>
      <visualize>true</visualize>
      <topic>__default_topic__</topic>
      <plugin filename="libgazebo_ros_imu_sensor.so" name="imu_plugin">
        <topicName>notspot_imu/base_link_orientation</topicName>
        <bodyName>imu_link</bodyName>
        <updateRateHZ>15.0</updateRateHZ>
        <gaussianNoise>0.0</gaussianNoise>
        <xyzOffset>0 0 0</xyzOffset>
        <rpyOffset>0 0 0</rpyOffset>
        <frameName>base_link</frameName>
        <initialOrientationAsReference>false</initialOrientationAsReference>
      </plugin>
      <pose>0 0 0 0 0 0</pose>
    </sensor>
  </gazebo>

  <!-- Joint state publisher plugin -->
  <gazebo>
    <plugin name="joint_state_publisher" filename="libgazebo_ros_joint_state_publisher.so">
        <robotNamespace>dingo_gazebo</robotNamespace>
        <jointName>FR_theta1, FR_theta2, FR_theta3, FL_theta1, FL_theta2,
                   FL_theta3, RR_theta1, RR_theta2, RR_theta3, RL_theta1,
                   RL_theta2, RL_theta3</jointName>
        <updateRate>100</updateRate>
    </plugin>
  </gazebo>

  <!-- Transmission -->
  <transmission name="tran1">
    <type>transmission_interface/SimpleTransmission</type>
    <joint name="FR_theta1">
      <hardwareInterface>hardware_interface/EffortJointInterface</hardwareInterface>
    </joint>
    <actuator name="motor1">
    <hardwareInterface>hardware_interface/EffortJointInterface</hardwareInterface>
    <mechanicalReduction>5</mechanicalReduction>
    </actuator>
  </transmission>

  <transmission name="tran2">
    <type>transmission_interface/SimpleTransmission</type>
    <joint name="FR_theta2">
      <hardwareInterface>hardware_interface/EffortJointInterface</hardwareInterface>
    </joint>
    <actuator name="motor2">
    <hardwareInterface>hardware_interface/EffortJointInterface</hardwareInterface>
    <mechanicalReduction>5</mechanicalReduction>
    </actuator>
  </transmission>

  <transmission name="tran3">
    <type>transmission_interface/SimpleTransmission</type>
    <joint name="FR_theta3">
      <hardwareInterface>hardware_interface/EffortJointInterface</hardwareInterface>
    </joint>
    <actuator name="motor3">
    <hardwareInterface>hardware_interface/EffortJointInterface</hardwareInterface>
    <mechanicalReduction>5</mechanicalReduction>
    </actuator>
  </transmission>

  <transmission name="tran4">
    <type>transmission_interface/SimpleTransmission</type>
    <joint name="FL_theta1">
      <hardwareInterface>hardware_interface/EffortJointInterface</hardwareInterface>
    </joint>
    <actuator name="motor4">
    <hardwareInterface>hardware_interface/EffortJointInterface</hardwareInterface>
    <mechanicalReduction>5</mechanicalReduction>
    </actuator>
  </transmission>

  <transmission name="tran5">
    <type>transmission_interface/SimpleTransmission</type>
    <joint name="FL_theta2">
      <hardwareInterface>hardware_interface/EffortJointInterface</hardwareInterface>
    </joint>
    <actuator name="motor5">
    <hardwareInterface>hardware_interface/EffortJointInterface</hardwareInterface>
    <mechanicalReduction>5</mechanicalReduction>
    </actuator>
  </transmission>

  <transmission name="tran6">
    <type>transmission_interface/SimpleTransmission</type>
    <joint name="FL_theta3">
      <hardwareInterface>hardware_interface/EffortJointInterface</hardwareInterface>
    </joint>
    <actuator name="motor6">
    <hardwareInterface>hardware_interface/EffortJointInterface</hardwareInterface>
    <mechanicalReduction>5</mechanicalReduction>
    </actuator>
  </transmission>

  <transmission name="tran7">
    <type>transmission_interface/SimpleTransmission</type>
    <joint name="RR_theta1">
      <hardwareInterface>hardware_interface/EffortJointInterface</hardwareInterface>
    </joint>
    <actuator name="motor7">
    <hardwareInterface>hardware_interface/EffortJointInterface</hardwareInterface>
    <mechanicalReduction>5</mechanicalReduction>
    </actuator>
  </transmission>

  <transmission name="tran8">
    <type>transmission_interface/SimpleTransmission</type>
    <joint name="RR_theta2">
      <hardwareInterface>hardware_interface/EffortJointInterface</hardwareInterface>
    </joint>
    <actuator name="motor8">
    <hardwareInterface>hardware_interface/EffortJointInterface</hardwareInterface>
    <mechanicalReduction>5</mechanicalReduction>
    </actuator>
  </transmission>

  <transmission name="tran9">
    <type>transmission_interface/SimpleTransmission</type>
    <joint name="RR_theta3">
      <hardwareInterface>hardware_interface/EffortJointInterface</hardwareInterface>
    </joint>
    <actuator name="motor9">
    <hardwareInterface>hardware_interface/EffortJointInterface</hardwareInterface>
    <mechanicalReduction>5</mechanicalReduction>
    </actuator>
  </transmission>

  <transmission name="tran10">
    <type>transmission_interface/SimpleTransmission</type>
    <joint name="RL_theta1">
      <hardwareInterface>hardware_interface/EffortJointInterface</hardwareInterface>
    </joint>
    <actuator name="motor10">
    <hardwareInterface>hardware_interface/EffortJointInterface</hardwareInterface>
    <mechanicalReduction>5</mechanicalReduction>
    </actuator>
  </transmission>

  <transmission name="tran11">
    <type>transmission_interface/SimpleTransmission</type>
    <joint name="RL_theta2">
      <hardwareInterface>hardware_interface/EffortJointInterface</hardwareInterface>
    </joint>
    <actuator name="motor11">
    <hardwareInterface>hardware_interface/EffortJointInterface</hardwareInterface>
    <mechanicalReduction>5</mechanicalReduction>
    </actuator>
  </transmission>

  <transmission name="tran12">
    <type>transmission_interface/SimpleTransmission</type>
    <joint name="RL_theta3">
      <hardwareInterface>hardware_interface/EffortJointInterface</hardwareInterface>
    </joint>
    <actuator name="motor12">
    <hardwareInterface>hardware_interface/EffortJointInterface</hardwareInterface>
    <mechanicalReduction>5</mechanicalReduction>
    </actuator>
  </transmission>

  <!-- FR4 friction -->
  <gazebo reference="FR4">
    <mu1>1.0</mu1>
    <mu2>1.0</mu2>
    <minDepth>0.0002</minDepth>
    <kp  value="1000000.0"/>
    <kd  value="100.0"/>
  </gazebo>

  <!-- FL4 friction -->
  <gazebo reference="FL4">
    <mu1>1.0</mu1>
    <mu2>1.0</mu2>
    <minDepth>0.0002</minDepth>
    <kp  value="1000000.0"/>
    <kd  value="100.0"/>
  </gazebo>

  <!-- RR4 friction -->
  <gazebo reference="RR4">
    <mu1>1.0</mu1>
    <mu2>1.0</mu2>
    <minDepth>0.0002</minDepth>
    <kp  value="1000000.0"/>
    <kd  value="100.0"/>
  </gazebo>

  <!-- RL4 friction -->
  <gazebo reference="RL4">
    <mu1>1.0</mu1>
    <mu2>1.0</mu2>
    <minDepth>0.0002</minDepth>
    <kp  value="1000000.0"/>
    <kd  value="100.0"/>
  </gazebo>


</robot>