<?xml version="1.0" encoding="utf-8"?>
<!-- This URDF was automatically created by SolidWorks to URDF Exporter! Originally created by Stephen Brawner (brawner@gmail.com) 
     Commit Version: 1.6.0-4-g7f85cfe  Build Version: 1.6.7995.38578
     For more information, please see http://wiki.ros.org/sw_urdf_exporter -->
<robot name="dingo" xmlns:xacro="http://www.ros.org/wiki/xacro">

  <!-- Maximum torque -->
  <xacro:property name="effort_limit" value="10" />

  <!-- base_link -->
  <link
    name="base_link">

    <!-- <inertial>
      <origin xyz="0.0 0.0 0.0"/>
      <mass value="2.50000000"/>
      <inertia ixx="0.00664756" ixy="0.00002187" ixz="0.00015428" iyy="0.02996945" iyz="-0.00000064" izz="0.03274274"/>
    </inertial>-->

    <!--
    <inertial>
      <origin xyz="0.0 0.00126483 -0.00622132"/>
      <mass value="2.5000000"/>
      <inertia ixx="0.00664756" ixy="0.00002187" ixz="0.00015428" iyy="0.02996945" iyz="-0.00000064" izz="0.03274274"/>
    </inertial>
    -->
  
    <inertial>
      <origin
        xyz="0 0 0"
        rpy="0 0 0" />
      <mass
        value="0.81776" />
      <inertia
        ixx="0.00058474"
        ixy="-1.0045E-06"
        ixz="1.0886E-08"
        iyy="0.00029699"
        iyz="3.2027E-08"
        izz="0.00063853" />
    </inertial>
    
    <!-- 
    <inertial>
      <origin xyz="-0.02679290 -0.00012097 0.00457177"/>
      <mass value="5.0000000"/>
      <inertia ixx="0.00732760" ixy="-0.00000000" ixz="0.00021940" iyy="0.02995798" iyz="-0.00000002" izz="0.03298004"/>
    </inertial>
    -->
    <visual>
      <origin
        xyz="0 0 0"
        rpy="0 0 0" />
      <geometry>
        <mesh
          filename="package://dingo_description/meshes/base_link.dae" />
      </geometry>
      <material
        name="">
        <color
          rgba="0.79216 0.81961 0.93333 1" />
      </material>
    </visual>
    <collision>
      <origin
        xyz="0 0 0"
        rpy="0 0 0" />
      <geometry>
        <mesh
          filename="package://dingo_description/meshes/base_collision.STL" />
      </geometry>
    </collision>
  </link>

  <!-- FL_link1 -->
  <link
    name="FL_link1">
    <inertial>
      <origin xyz="0 0 0"/>
      <mass value="0.30000000"/>
      <inertia ixx="0.00019300" ixy="0.00000000" ixz="0.00000000" iyy="0.00014890" iyz="0.00000000" izz="0.00012410"/>
    </inertial>
    <visual>
      <origin
        xyz="0 0 0"
        rpy="0 0 0" />
      <geometry>
        <mesh
          filename="package://dingo_description/meshes/FL_link1.dae" />
      </geometry>
      <material
        name="">
        <color
          rgba="0.79216 0.81961 0.93333 1" />
      </material>
    </visual>
    <collision>
      <origin
        xyz="0 0 0"
        rpy="0 0 0" />
      <geometry>
        <mesh
          filename="package://dingo_description/meshes/L_link1_collision.STL" />
      </geometry>
    </collision>
  </link>

  <!-- FL_link2 -->
  <link
    name="FL_link2">
    <inertial>
      <origin xyz="0 0 0"/>
      <mass value="0.10000000"/>
      <inertia ixx="0.00000700" ixy="0.00000000" ixz="0.00000444" iyy="0.00017260" iyz="0.00000000" izz="0.00017568"/>
    </inertial>

    <visual>
      <origin
        xyz="0 0 0"
        rpy="0 0 0" />
      <geometry>
        <mesh
          filename="package://dingo_description/meshes/L_link2.dae" />
      </geometry>
      <material
        name="">
        <color
          rgba="0.79216 0.81961 0.93333 1" />
      </material>
    </visual>
    <collision>
      <origin
        xyz="0 0 0"
        rpy="0 0 0" />
      <geometry>
        <mesh
          filename="package://dingo_description/meshes/L_link2_collision.STL" />
      </geometry>
    </collision>
  </link>

  <!-- FL_link3 -->
  <link
    name="FL_link3">
    <inertial>
      <origin xyz="0 0 0"/>
      <mass value="0.10000000"/>
      <inertia ixx="0.00000936" ixy="-0.00001360" ixz="-0.00000319" iyy="0.00019747" iyz="-0.00000027" izz="0.00019702"/>
    </inertial>

    <visual>
      <origin
        xyz="0 0 0"
        rpy="0 0 0" />
      <geometry>
        <mesh
          filename="package://dingo_description/meshes/L_link3.dae" />
      </geometry>
      <material
        name="">
        <color
          rgba="0.79216 0.81961 0.93333 1" />
      </material>
    </visual>
    <collision>
      <origin
        xyz="0 0 0"
        rpy="0 0 0" />
      <geometry>
        <mesh
          filename="package://dingo_description/meshes/L_link3_collision.STL" />
      </geometry>
    </collision>
  </link>

  <!-- FL_link4 -->
  <link
    name="FL_link4">
    <inertial>
      <origin xyz="0 0 0"/>
      <mass value="0.02000000"/>
      <inertia ixx="0.00000060" ixy="-0.00000013" ixz="0.00000000" iyy="0.00000058" iyz="0.00000000" izz="0.00000045"/>
    </inertial>

    <visual>
      <origin
        xyz="0 0 0"
        rpy="0 0 0" />
      <geometry>
        <mesh
          filename="package://dingo_description/meshes/link4.dae" />
      </geometry>
      <material
        name="">
        <color
          rgba="0.79216 0.81961 0.93333 1" />
      </material>
    </visual>
    <collision>
      <origin
        xyz="0 0 0"
        rpy="0 0 0" />
      <geometry>
        <mesh
          filename="package://dingo_description/meshes/link4_collision.STL" />
      </geometry>
    </collision>
  </link>

  <!-- FR_link1 -->
  <link
    name="FR_link1">
    <inertial>
      <origin xyz="0 0 0"/>
      <mass value="0.30000000"/>
      <inertia ixx="0.00019300" ixy="0.00000000" ixz="0.00000000" iyy="0.00014890" iyz="0.00000000" izz="0.00012410"/>
    </inertial>

    <visual>
      <origin
        xyz="0 0 0"
        rpy="0 0 0" />
      <geometry>
        <mesh
          filename="package://dingo_description/meshes/FR_link1.dae" />
      </geometry>
      <material
        name="">
        <color
          rgba="0.79216 0.81961 0.93333 1" />
      </material>
    </visual>
    <collision>
      <origin
        xyz="0 0 0"
        rpy="0 0 0" />
      <geometry>
        <mesh
          filename="package://dingo_description/meshes/R_link1_collision.STL" />
      </geometry>
    </collision>
  </link>

  <!-- FR_link2 -->
  <link
    name="FR_link2">
    <inertial>
      <origin xyz="0 0 0"/>
      <mass value="0.10000000"/>
      <inertia ixx="0.00000700" ixy="0.00000000" ixz="0.00000444" iyy="0.00017260" iyz="0.00000000" izz="0.00017568"/>
    </inertial>

    <visual>
      <origin
        xyz="0 0 0"
        rpy="0 0 0" />
      <geometry>
        <mesh
          filename="package://dingo_description/meshes/R_link2.dae" />
      </geometry>
      <material
        name="">
        <color
          rgba="0.79216 0.81961 0.93333 1" />
      </material>
    </visual>
    <collision>
      <origin
        xyz="0 0 0"
        rpy="0 0 0" />
      <geometry>
        <mesh
          filename="package://dingo_description/meshes/R_link2_collision.STL" />
      </geometry>
    </collision>
  </link>

  <!-- FR_link3 -->
  <link
    name="FR_link3">
    <inertial>
      <origin xyz="0 0 0"/>
      <mass value="0.10000000"/>
      <inertia ixx="0.00000936" ixy="-0.00001360" ixz="-0.00000319" iyy="0.00019747" iyz="-0.00000027" izz="0.00019702"/>
    </inertial>

    <visual>
      <origin
        xyz="0 0 0"
        rpy="0 0 0" />
      <geometry>
        <mesh
          filename="package://dingo_description/meshes/R_link3.dae" />
      </geometry>
      <material
        name="">
        <color
          rgba="0.79216 0.81961 0.93333 1" />
      </material>
    </visual>
    <collision>
      <origin
        xyz="0 0 0"
        rpy="0 0 0" />
      <geometry>
        <mesh
          filename="package://dingo_description/meshes/R_link3_collision.STL" />
      </geometry>
    </collision>
  </link>

  <!-- FR_link4 -->
  <link
    name="FR_link4">
    <inertial>
      <origin xyz="0 0 0"/>
      <mass value="0.02000000"/>
      <inertia ixx="0.00000060" ixy="-0.00000013" ixz="0.00000000" iyy="0.00000058" iyz="0.00000000" izz="0.00000045"/>
    </inertial>

    <visual>
      <origin
        xyz="0 0 0"
        rpy="0 0 0" />
      <geometry>
        <mesh
          filename="package://dingo_description/meshes/link4.dae" />
      </geometry>
      <material
        name="">
        <color
          rgba="0.79216 0.81961 0.93333 1" />
      </material>
    </visual>
    <collision>
      <origin
        xyz="0 0 0"
        rpy="0 0 0" />
      <geometry>
        <mesh
          filename="package://dingo_description/meshes/link4_collision.STL" />
      </geometry>
    </collision>
  </link>

  <!-- RL_link1 -->
  <link
    name="RL_link1">
    <inertial>
      <origin xyz="0 0 0"/>
      <mass value="0.30000000"/>
      <inertia ixx="0.00019300" ixy="0.00000000" ixz="0.00000000" iyy="0.00014890" iyz="0.00000000" izz="0.00012410"/>
    </inertial>

    <visual>
      <origin
        xyz="0 0 0"
        rpy="0 0 0" />
      <geometry>
        <mesh
          filename="package://dingo_description/meshes/RL_link1.dae" />
      </geometry>
      <material
        name="">
        <color
          rgba="0.79216 0.81961 0.93333 1" />
      </material>
    </visual>
    <collision>
      <origin
        xyz="0 0 0"
        rpy="0 0 0" />
      <geometry>
        <mesh
          filename="package://dingo_description/meshes/L_link1_collision.STL" />
      </geometry>
    </collision>
  </link>
  
  <!-- RL_link2 -->
  <link
    name="RL_link2">
    <inertial>
      <origin xyz="0 0 0"/>
      <mass value="0.10000000"/>
      <inertia ixx="0.00000700" ixy="0.00000000" ixz="0.00000444" iyy="0.00017260" iyz="0.00000000" izz="0.00017568"/>
    </inertial>

    <visual>
      <origin
        xyz="0 0 0"
        rpy="0 0 0" />
      <geometry>
        <mesh
          filename="package://dingo_description/meshes/L_link2.dae" />
      </geometry>
      <material
        name="">
        <color
          rgba="0.79216 0.81961 0.93333 1" />
      </material>
    </visual>
    <collision>
      <origin
        xyz="0 0 0"
        rpy="0 0 0" />
      <geometry>
        <mesh
          filename="package://dingo_description/meshes/L_link2_collision.STL" />
      </geometry>
    </collision>
  </link>

  <!-- RL_link3 -->
  <link
    name="RL_link3">
    <inertial>
      <origin xyz="0 0 0"/>
      <mass value="0.10000000"/>
      <inertia ixx="0.00000936" ixy="-0.00001360" ixz="-0.00000319" iyy="0.00019747" iyz="-0.00000027" izz="0.00019702"/>
    </inertial>

    <visual>
      <origin
        xyz="0 0 0"
        rpy="0 0 0" />
      <geometry>
        <mesh
          filename="package://dingo_description/meshes/L_link3.dae" />
      </geometry>
      <material
        name="">
        <color
          rgba="0.79216 0.81961 0.93333 1" />
      </material>
    </visual>
    <collision>
      <origin
        xyz="0 0 0"
        rpy="0 0 0" />
      <geometry>
        <mesh
          filename="package://dingo_description/meshes/L_link3_collision.STL" />
      </geometry>
    </collision>
  </link>

  <!-- RL_link4 -->
  <link
    name="RL_link4">
    <inertial>
      <origin xyz="0 0 0"/>
      <mass value="0.02000000"/>
      <inertia ixx="0.00000060" ixy="-0.00000013" ixz="0.00000000" iyy="0.00000058" iyz="0.00000000" izz="0.00000045"/>
    </inertial>

    <visual>
      <origin
        xyz="0 0 0"
        rpy="0 0 0" />
      <geometry>
        <mesh
          filename="package://dingo_description/meshes/link4.dae" />
      </geometry>
      <material
        name="">
        <color
          rgba="0.79216 0.81961 0.93333 1" />
      </material>
    </visual>
    <collision>
      <origin
        xyz="0 0 0"
        rpy="0 0 0" />
      <geometry>
        <mesh
          filename="package://dingo_description/meshes/link4_collision.STL" />
      </geometry>
    </collision>
  </link>

  <!-- RR_link1 -->
  <link
    name="RR_link1">
    <inertial>
      <origin xyz="0 0 0"/>
      <mass value="0.30000000"/>
      <inertia ixx="0.00019300" ixy="0.00000000" ixz="0.00000000" iyy="0.00014890" iyz="0.00000000" izz="0.00012410"/>
    </inertial>

    <visual>
      <origin
        xyz="0 0 0"
        rpy="0 0 0" />
      <geometry>
        <mesh
          filename="package://dingo_description/meshes/RR_link1.dae" />
      </geometry>
      <material
        name="">
        <color
          rgba="0.79216 0.81961 0.93333 1" />
      </material>
    </visual>
    <collision>
      <origin
        xyz="0 0 0"
        rpy="0 0 0" />
      <geometry>
        <mesh
          filename="package://dingo_description/meshes/R_link1_collision.STL" />
      </geometry>
    </collision>
  </link>

  <!-- RR_link2 -->
  <link
    name="RR_link2">
    <inertial>
      <origin xyz="0 0 0"/>
      <mass value="0.10000000"/>
      <inertia ixx="0.00000700" ixy="0.00000000" ixz="0.00000444" iyy="0.00017260" iyz="0.00000000" izz="0.00017568"/>
    </inertial>

    <visual>
      <origin
        xyz="0 0 0"
        rpy="0 0 0" />
      <geometry>
        <mesh
          filename="package://dingo_description/meshes/R_link2.dae" />
      </geometry>
      <material
        name="">
        <color
          rgba="0.79216 0.81961 0.93333 1" />
      </material>
    </visual>
    <collision>
      <origin
        xyz="0 0 0"
        rpy="0 0 0" />
      <geometry>
        <mesh
          filename="package://dingo_description/meshes/R_link2_collision.STL" />
      </geometry>
    </collision>
  </link>

  <!-- RR_link3 -->
  <link
    name="RR_link3">
    <inertial>
      <origin xyz="0 0 0"/>
      <mass value="0.10000000"/>
      <inertia ixx="0.00000936" ixy="-0.00001360" ixz="-0.00000319" iyy="0.00019747" iyz="-0.00000027" izz="0.00019702"/>
    </inertial>

    <visual>
      <origin
        xyz="0 0 0"
        rpy="0 0 0" />
      <geometry>
        <mesh
          filename="package://dingo_description/meshes/R_link3.dae" />
      </geometry>
      <material
        name="">
        <color
          rgba="0.79216 0.81961 0.93333 1" />
      </material>
    </visual>
    <collision>
      <origin
        xyz="0 0 0"
        rpy="0 0 0" />
      <geometry>
        <mesh
          filename="package://dingo_description/meshes/R_link3_collision.STL" />
      </geometry>
    </collision>
  </link>

  <!-- RR_link4 -->
  <link
    name="RR_link4">
    <inertial>
      <origin xyz="0 0 0"/>
      <mass value="0.02000000"/>
      <inertia ixx="0.00000060" ixy="-0.00000013" ixz="0.00000000" iyy="0.00000058" iyz="0.00000000" izz="0.00000045"/>
    </inertial>

    <visual>
      <origin
        xyz="0 0 0"
        rpy="0 0 0" />
      <geometry>
        <mesh
          filename="package://dingo_description/meshes/link4.dae" />
      </geometry>
      <material
        name="">
        <color
          rgba="0.79216 0.81961 0.93333 1" />
      </material>
    </visual>
    <collision>
      <origin
        xyz="0 0 0"
        rpy="0 0 0" />
      <geometry>
        <mesh
          filename="package://dingo_description/meshes/link4_collision.STL" />
      </geometry>
    </collision>
  </link>



  <!-- JOINTS -->
  
  <joint
    name="FL_theta1"
    type="revolute">
    <origin
      xyz="0.11165 0.061 -0.0144"
      rpy="1.5708 0 1.5708" />
    <parent
      link="base_link" />
    <child
      link="FL_link1" />
    <axis
      xyz="0 0 1" />
    <limit
      lower="-0.785398"
      upper="0.785398"
      effort="${effort_limit}"
      velocity="3" />
    <joint_properties damping="1000.0" friction="1000.0"/>
  </joint>
  <joint
    name="FL_theta2"
    type="revolute">
    <origin
      xyz="0.0496000007984339 0.014400000013256 0"
      rpy="1.57079634307336 1.57079568414183 -1.57079631051644" />
    <parent
      link="FL_link1" />
    <child
      link="FL_link2" />
    <axis
      xyz="0 0 1" />
    <limit
      lower="-3"
      upper="3"
      effort="${effort_limit}"
      velocity="3" />
    <joint_properties damping="1000.0" friction="1000.0"/>
  </joint>
  <joint
    name="FL_theta3"
    type="revolute">
    <origin
      xyz="0.129999999999897 0 0"
      rpy="0 0 1.57079594774422" />
    <parent
      link="FL_link2" />
    <child
      link="FL_link3" />
    <axis
      xyz="0 0 1" />
    <limit
      lower="-3"
      upper="3"
      effort="${effort_limit}"
      velocity="3" />
    <joint_properties damping="1000.0" friction="1000.0"/>
  </joint>
  <joint
    name="FL_foot"
    type="fixed">
    <origin
      xyz="0.138136646352288 0 0"
      rpy="0 0 0" />
    <parent
      link="FL_link3" />
    <child
      link="FL_link4" />
    <axis
      xyz="0 0 0" />
  </joint>



  <joint
    name="FR_theta1"
    type="revolute">
    <origin
      xyz="0.111650000000002 -0.0609999999999988 -0.0144000000000242"
      rpy="1.57079632679492 0 1.5707963267949" />
    <parent
      link="base_link" />
    <child
      link="FR_link1" />
    <axis
      xyz="0 0 -1" />
    <limit
      lower="-0.785398"
      upper="0.785398"
      effort="${effort_limit}"
      velocity="3" />
    <joint_properties damping="1000.0" friction="1000.0"/>
  </joint>
  <joint
    name="FR_theta2"
    type="revolute">
    <origin
      xyz="-0.0495999992169121 0.0144000000000242 0"
      rpy="1.57079632309575 1.57079572077363 -1.57079633049404" />
    <parent
      link="FR_link1" />
    <child
      link="FR_link2" />
    <axis
      xyz="0 0 1" />
    <limit
      lower="-3"
      upper="3"
      effort="${effort_limit}"
      velocity="3" />
    <joint_properties damping="1000.0" friction="1000.0"/>
  </joint>
  <joint
    name="FR_theta3"
    type="revolute">
    <origin
      xyz="0.13000000353672 0 0"
      rpy="0 0 1.57079598438978" />
    <parent
      link="FR_link2" />
    <child
      link="FR_link3" />
    <axis
      xyz="0 0 1" />
    <limit
      lower="-3"
      upper="3"
      effort="${effort_limit}"
      velocity="3" />
    <joint_properties damping="1000.0" friction="1000.0"/>
  </joint>
  <joint
    name="FR_foot"
    type="fixed">
    <origin
      xyz="0.13813664635243 0 0"
      rpy="0 0 0" />
    <parent
      link="FR_link3" />
    <child
      link="FR_link4" />
    <axis
      xyz="0 0 0" />
  </joint>




  <joint
    name="RL_theta1"
    type="revolute">
    <origin
      xyz="-0.11165 0.061 -0.0144"
      rpy="1.5708 0 1.5708" />
    <parent
      link="base_link" />
    <child
      link="RL_link1" />
    <axis
      xyz="0 0 1" />
    <limit
      lower="-0.785398"
      upper="0.785398"
      effort="${effort_limit}"
      velocity="3" />
    <joint_properties damping="1000.0" friction="1000.0"/>
  </joint>
  <joint
    name="RL_theta2"
    type="revolute">
    <origin
      xyz="0.0496000007984574 0.014399999996394 0"
      rpy="1.5707963301177 1.57079568414183 -1.57079632347209" />
    <parent
      link="RL_link1" />
    <child
      link="RL_link2" />
    <axis
      xyz="0 0 1" />
    <limit
      lower="-3"
      upper="3"
      effort="${effort_limit}"
      velocity="3" />
    <joint_properties damping="1000.0" friction="1000.0"/>
  </joint>
  <joint
    name="RL_theta3"
    type="revolute">
    <origin
      xyz="0.129999999994849 0 0"
      rpy="0 0 1.57079594787326" />
    <parent
      link="RL_link2" />
    <child
      link="RL_link3" />
    <axis
      xyz="0 0 0.999999999999979" />
    <limit
      lower="-3"
      upper="3"
      effort="${effort_limit}"
      velocity="3" />
    <joint_properties damping="1000.0" friction="1000.0"/>
  </joint>
  <joint
    name="RL_foot"
    type="fixed">
    <origin
      xyz="0.138136646352323 0 0"
      rpy="0 0 0" />
    <parent
      link="RL_link3" />
    <child
      link="RL_link4" />
    <axis
      xyz="0 0 0" />
  </joint>



  <joint
    name="RR_theta1"
    type="revolute">
    <origin
      xyz="-0.111650000000003 -0.0609999999999995 -0.0144000000000178"
      rpy="1.57079632679492 0 1.5707963267949" />
    <parent
      link="base_link" />
    <child
      link="RR_link1" />
    <axis
      xyz="0 0 -1" />
    <limit
      lower="-0.785398"
      upper="0.785398"
      effort="${effort_limit}"
      velocity="3" />
    <joint_properties damping="1000.0" friction="1000.0"/>
  </joint>
  <joint
    name="RR_theta2"
    type="revolute">
    <origin
      xyz="-0.0495999992169147 0.0144000000000178 0"
      rpy="1.57079631992506 1.57079572077363 -1.57079633366473" />
    <parent
      link="RR_link1" />
    <child
      link="RR_link2" />
    <axis
      xyz="0 0 1" />
    <limit
      lower="-3"
      upper="3"
      effort="${effort_limit}"
      velocity="3" />
    <joint_properties damping="1000.0" friction="1000.0"/>
  </joint>
  <joint
    name="RR_theta3"
    type="revolute">
    <origin
      xyz="0.13000000353672 0 0"
      rpy="0 0 1.57079598438978" />
    <parent
      link="RR_link2" />
    <child
      link="RR_link3" />
    <axis
      xyz="0 0 0.999999999999998" />
    <limit
      lower="-3"
      upper="3"
      effort="${effort_limit}"
      velocity="3" />
    <joint_properties damping="1000.0" friction="1000.0"/>
  </joint>
  <joint
    name="RR_foot"
    type="fixed">
    <origin
      xyz="0.138136646352431 0 0"
      rpy="0 0 0" />
    <parent
      link="RR_link3" />
    <child
      link="RR_link4" />
    <axis
      xyz="0 0 0" />
  </joint>





  <!-- ROS control plugin -->
  <gazebo>
    <plugin name="gazebo_ros_control" filename="libgazebo_ros_control.so">
      <robotNamespace>dingo_controller</robotNamespace>
    </plugin>
  </gazebo>


  <!-- IMU sensor -->
  <gazebo reference="base_link">
    <gravity>true</gravity>
    <sensor name="imu_sensor" type="imu">
      <always_on>true</always_on>
      <update_rate>100</update_rate>
      <visualize>true</visualize>
      <topic>__default_topic__</topic>
      <plugin filename="libgazebo_ros_imu_sensor.so" name="imu_plugin">
        <topicName>notspot_imu/base_link_orientation</topicName>
        <bodyName>imu_link</bodyName>
        <updateRateHZ>15.0</updateRateHZ>
        <gaussianNoise>0.0</gaussianNoise>
        <xyzOffset>0 0 0</xyzOffset>
        <rpyOffset>0 0 0</rpyOffset>
        <frameName>base_link</frameName>
        <initialOrientationAsReference>false</initialOrientationAsReference>
      </plugin>
      <pose>0 0 0 0 0 0</pose>
    </sensor>
  </gazebo>

  <!-- Joint state publisher plugin -->
  <gazebo>
    <plugin name="joint_state_publisher" filename="libgazebo_ros_joint_state_publisher.so">
        <robotNamespace>dingo_gazebo</robotNamespace>
        <jointName>FR_theta1, FR_theta2, FR_theta3, FL_theta1, FL_theta2,
                   FL_theta3, RR_theta1, RR_theta2, RR_theta3, RL_theta1,
                   RL_theta2, RL_theta3</jointName>
        <updateRate>100</updateRate>
    </plugin>
  </gazebo>

  <!-- Transmission -->
  <transmission name="tran1">
    <type>transmission_interface/SimpleTransmission</type>
    <joint name="FR_theta1">
      <hardwareInterface>hardware_interface/EffortJointInterface</hardwareInterface>
    </joint>
    <actuator name="motor1">
    <hardwareInterface>hardware_interface/EffortJointInterface</hardwareInterface>
    <mechanicalReduction>5</mechanicalReduction>
    </actuator>
  </transmission>

  <transmission name="tran2">
    <type>transmission_interface/SimpleTransmission</type>
    <joint name="FR_theta2">
      <hardwareInterface>hardware_interface/EffortJointInterface</hardwareInterface>
    </joint>
    <actuator name="motor2">
    <hardwareInterface>hardware_interface/EffortJointInterface</hardwareInterface>
    <mechanicalReduction>5</mechanicalReduction>
    </actuator>
  </transmission>

  <transmission name="tran3">
    <type>transmission_interface/SimpleTransmission</type>
    <joint name="FR_theta3">
      <hardwareInterface>hardware_interface/EffortJointInterface</hardwareInterface>
    </joint>
    <actuator name="motor3">
    <hardwareInterface>hardware_interface/EffortJointInterface</hardwareInterface>
    <mechanicalReduction>5</mechanicalReduction>
    </actuator>
  </transmission>

  <transmission name="tran4">
    <type>transmission_interface/SimpleTransmission</type>
    <joint name="FL_theta1">
      <hardwareInterface>hardware_interface/EffortJointInterface</hardwareInterface>
    </joint>
    <actuator name="motor4">
    <hardwareInterface>hardware_interface/EffortJointInterface</hardwareInterface>
    <mechanicalReduction>5</mechanicalReduction>
    </actuator>
  </transmission>

  <transmission name="tran5">
    <type>transmission_interface/SimpleTransmission</type>
    <joint name="FL_theta2">
      <hardwareInterface>hardware_interface/EffortJointInterface</hardwareInterface>
    </joint>
    <actuator name="motor5">
    <hardwareInterface>hardware_interface/EffortJointInterface</hardwareInterface>
    <mechanicalReduction>5</mechanicalReduction>
    </actuator>
  </transmission>

  <transmission name="tran6">
    <type>transmission_interface/SimpleTransmission</type>
    <joint name="FL_theta3">
      <hardwareInterface>hardware_interface/EffortJointInterface</hardwareInterface>
    </joint>
    <actuator name="motor6">
    <hardwareInterface>hardware_interface/EffortJointInterface</hardwareInterface>
    <mechanicalReduction>5</mechanicalReduction>
    </actuator>
  </transmission>

  <transmission name="tran7">
    <type>transmission_interface/SimpleTransmission</type>
    <joint name="RR_theta1">
      <hardwareInterface>hardware_interface/EffortJointInterface</hardwareInterface>
    </joint>
    <actuator name="motor7">
    <hardwareInterface>hardware_interface/EffortJointInterface</hardwareInterface>
    <mechanicalReduction>5</mechanicalReduction>
    </actuator>
  </transmission>

  <transmission name="tran8">
    <type>transmission_interface/SimpleTransmission</type>
    <joint name="RR_theta2">
      <hardwareInterface>hardware_interface/EffortJointInterface</hardwareInterface>
    </joint>
    <actuator name="motor8">
    <hardwareInterface>hardware_interface/EffortJointInterface</hardwareInterface>
    <mechanicalReduction>5</mechanicalReduction>
    </actuator>
  </transmission>

  <transmission name="tran9">
    <type>transmission_interface/SimpleTransmission</type>
    <joint name="RR_theta3">
      <hardwareInterface>hardware_interface/EffortJointInterface</hardwareInterface>
    </joint>
    <actuator name="motor9">
    <hardwareInterface>hardware_interface/EffortJointInterface</hardwareInterface>
    <mechanicalReduction>5</mechanicalReduction>
    </actuator>
  </transmission>

  <transmission name="tran10">
    <type>transmission_interface/SimpleTransmission</type>
    <joint name="RL_theta1">
      <hardwareInterface>hardware_interface/EffortJointInterface</hardwareInterface>
    </joint>
    <actuator name="motor10">
    <hardwareInterface>hardware_interface/EffortJointInterface</hardwareInterface>
    <mechanicalReduction>5</mechanicalReduction>
    </actuator>
  </transmission>

  <transmission name="tran11">
    <type>transmission_interface/SimpleTransmission</type>
    <joint name="RL_theta2">
      <hardwareInterface>hardware_interface/EffortJointInterface</hardwareInterface>
    </joint>
    <actuator name="motor11">
    <hardwareInterface>hardware_interface/EffortJointInterface</hardwareInterface>
    <mechanicalReduction>5</mechanicalReduction>
    </actuator>
  </transmission>

  <transmission name="tran12">
    <type>transmission_interface/SimpleTransmission</type>
    <joint name="RL_theta3">
      <hardwareInterface>hardware_interface/EffortJointInterface</hardwareInterface>
    </joint>
    <actuator name="motor12">
    <hardwareInterface>hardware_interface/EffortJointInterface</hardwareInterface>
    <mechanicalReduction>5</mechanicalReduction>
    </actuator>
  </transmission>

  <!-- FR4 friction -->
  <gazebo reference="FR_link4">
    <mu1>1.0</mu1>
    <mu2>1.0</mu2>
    <minDepth>0.0002</minDepth>
    <kp  value="1000000.0"/>
    <kd  value="100.0"/>
  </gazebo>

  <!-- FL4 friction -->
  <gazebo reference="FL_link4">
    <mu1>1.0</mu1>
    <mu2>1.0</mu2>
    <minDepth>0.0002</minDepth>
    <kp  value="1000000.0"/>
    <kd  value="100.0"/>
  </gazebo>

  <!-- RR4 friction -->
  <gazebo reference="RR_link4">
    <mu1>1.0</mu1>
    <mu2>1.0</mu2>
    <minDepth>0.0002</minDepth>
    <kp  value="1000000.0"/>
    <kd  value="100.0"/>
  </gazebo>

  <!-- RL4 friction -->
  <gazebo reference="RL_link4">
    <mu1>1.0</mu1>
    <mu2>1.0</mu2>
    <minDepth>0.0002</minDepth>
    <kp  value="1000000.0"/>
    <kd  value="100.0"/>
  </gazebo>


</robot>